<mujoco model="ur5eCopy">
  <compiler angle="radian" meshdir="assets"/>

  <!--  <option integrator="implicitfast"/>-->

  <default>
    <default class="ur5eCopy">
      <material specular="0.5" shininess="0.25"/>
      <joint axis="0 1 0" range="-6.28319 6.28319" armature="0.1"/>
      <general gaintype="fixed" biastype="affine" ctrlrange="-6.2831 6.2831" gainprm="2000" biasprm="0 -2000 -400" forcerange="-150 150"/>
      <default class="size3Copy">
        <default class="size3Copy_limited">
          <joint range="-3.1415 3.1415"/>
          <general ctrlrange="-3.1415 3.1415"/>
        </default>
      </default>
      <default class="size1Copy">
        <general gainprm="500" biasprm="0 -500 -100" forcerange="-28 28"/>
      </default>
      <default class="visualCopy">
        <geom type="mesh" contype="0" conaffinity="0" group="2"/>
      </default>
      <default class="collisionCopy">
        <geom type="capsule" group="3"/>
        <default class="eef_collisionCopy">
          <geom type="cylinder"/>
        </default>
      </default>
      <site size="0.001" rgba="0.5 0.5 0.5 0.3" group="4"/>
    </default>
  </default>

  <asset>
    <material class="ur5eCopy" name="black_arm2" rgba="0.033 0.033 0.033 1"/>
    <material class="ur5eCopy" name="jointgray_arm2" rgba="0.278 0.278 0.278 1"/>
    <material class="ur5eCopy" name="linkgray_arm2" rgba="0.82 0.82 0.82 1"/>
    <material class="ur5eCopy" name="urblue_arm2" rgba="0.49 0.678 0.8 1"/>

    <mesh file="base_0.stl"/>
    <mesh file="base_1.stl"/>
    <mesh file="shoulder_0.stl"/>
    <mesh file="shoulder_1.stl"/>
    <mesh file="shoulder_2.stl"/>
    <mesh file="upperarm_0.stl"/>
    <mesh file="upperarm_1.stl"/>
    <mesh file="upperarm_2.stl"/>
    <mesh file="upperarm_3.stl"/>
    <mesh file="forearm_0.stl"/>
    <mesh file="forearm_1.stl"/>
    <mesh file="forearm_2.stl"/>
    <mesh file="forearm_3.stl"/>
    <mesh file="wrist1_0.stl"/>
    <mesh file="wrist1_1.stl"/>
    <mesh file="wrist1_2.stl"/>
    <mesh file="wrist2_0.stl"/>
    <mesh file="wrist2_1.stl"/>
    <mesh file="wrist2_2.stl"/>
    <mesh file="wrist3.stl"/>
  </asset>

  <worldbody>
    <light name="spotlight_arm2" mode="targetbodycom" target="wrist_2_link_arm2" pos="0 -1 2"/>
    <body name="base_arm2" pos="0 0.5 0" quat="1 0 0 0" childclass="ur5eCopy">
      <inertial mass="4.0" pos="0 0 0" diaginertia="0.00443333156 0.00443333156 0.0072"/>
      <geom mesh="base_0" material="black_arm2" class="visualCopy"/>
      <geom mesh="base_1" material="jointgray_arm2" class="visualCopy"/>
      <body name="shoulder_link_arm2" pos="0 0 0.163">
        <inertial mass="3.7" pos="0 0 0" diaginertia="0.0102675 0.0102675 0.00666"/>
        <joint name="shoulder_pan_joint_arm2" class="size3Copy" axis="0 0 1"/>
        <geom mesh="shoulder_0" material="urblue_arm2" class="visualCopy"/>
        <geom mesh="shoulder_1" material="black_arm2" class="visualCopy"/>
        <geom mesh="shoulder_2" material="jointgray_arm2" class="visualCopy"/>
        <geom class="collisionCopy" size="0.06 0.06" pos="0 0 -0.04"/>
        <body name="upper_arm_link_arm2" pos="0 0.138 0" quat="1 0 0 0">
          <inertial mass="8.393" pos="0 0 0.2125" diaginertia="0.133886 0.133886 0.0151074"/>
          <joint name="shoulder_lift_joint_arm2" class="size3Copy"/>
          <geom mesh="upperarm_0" material="linkgray_arm2" class="visualCopy"/>
          <geom mesh="upperarm_1" material="black_arm2" class="visualCopy"/>
          <geom mesh="upperarm_2" material="jointgray_arm2" class="visualCopy"/>
          <geom mesh="upperarm_3" material="urblue_arm2" class="visualCopy"/>
          <geom class="collisionCopy" pos="0 -0.04 0" quat="1 1 0 0" size="0.06 0.06"/>
          <geom class="collisionCopy" size="0.05 0.2" pos="0 0 0.2"/>
          <body name="forearm_link_arm2" pos="0 -0.131 0.425">
            <inertial mass="2.275" pos="0 0 0.196" diaginertia="0.0311796 0.0311796 0.004095"/>
            <joint name="elbow_joint_arm2" class="size3Copy_limited"/>
            <geom mesh="forearm_0" material="urblue_arm2" class="visualCopy"/>
            <geom mesh="forearm_1" material="linkgray_arm2" class="visualCopy"/>
            <geom mesh="forearm_2" material="black_arm2" class="visualCopy"/>
            <geom mesh="forearm_3" material="jointgray_arm2" class="visualCopy"/>
            <geom class="collisionCopy" pos="0 0.08 0" quat="1 1 0 0" size="0.055 0.06"/>
            <geom class="collisionCopy" size="0.038 0.19" pos="0 0 0.2"/>
            <body name="wrist_1_link_arm2" pos="0 0 0.392" quat="1 0 0 0">
              <inertial mass="1.219" pos="0 0.127 0" diaginertia="0.0025599 0.0025599 0.0021942"/>
              <joint name="wrist_1_joint_arm2" class="size1Copy"/>
              <geom mesh="wrist1_0" material="black_arm2" class="visualCopy"/>
              <geom mesh="wrist1_1" material="urblue_arm2" class="visualCopy"/>
              <geom mesh="wrist1_2" material="jointgray_arm2" class="visualCopy"/>
              <geom class="collisionCopy" pos="0 0.05 0" quat="1 1 0 0" size="0.04 0.07"/>
              <body name="wrist_2_link_arm2" pos="0 0.127 0">
                <inertial mass="1.219" pos="0 0 0.1" diaginertia="0.0025599 0.0021942 0.0025599"/>
                <joint name="wrist_2_joint_arm2" axis="0 0 1" class="size1Copy"/>
                <geom mesh="wrist2_0" material="black_arm2" class="visualCopy"/>
                <geom mesh="wrist2_1" material="urblue_arm2" class="visualCopy"/>
                <geom mesh="wrist2_2" material="jointgray_arm2" class="visualCopy"/>
                <geom class="collisionCopy" size="0.04 0.06" pos="0 0 0.04"/>
                <geom class="collisionCopy" pos="0 0.02 0.1" quat="1 1 0 0" size="0.04 0.04"/>
                <body name="wrist_3_link_arm2" pos="0 0 0.1">
                  <inertial mass="0.1889" pos="0 0.0771683 0" quat="1 0 0 1" diaginertia="0.000132134 9.90863e-05 9.90863e-05"/>
                  <joint name="wrist_3_joint_arm2" class="size1Copy"/>
                  <geom material="linkgray_arm2" mesh="wrist3" class="visualCopy"/>
                  <geom class="eef_collisionCopy" pos="0 0.08 0" quat="1 1 0 0" size="0.04 0.02"/>
                  <site name="attachment_site_arm2" pos="0 0.1 0" quat="-1 1 0 0"/>
                </body>
              </body>
            </body>
          </body>
        </body>
      </body>
    </body>
  </worldbody>

  <actuator>
    <motor name="shoulder_pan_arm2" joint="shoulder_pan_joint_arm2"/>
    <motor name="shoulder_lift_arm2" joint="shoulder_lift_joint_arm2"/>
    <motor name="elbow_arm2" joint="elbow_joint_arm2"/>
    <motor name="wrist_1_arm2" joint="wrist_1_joint_arm2"/>
    <motor name="wrist_2_arm2" joint="wrist_2_joint_arm2"/>
    <motor name="wrist_3_arm2" joint="wrist_3_joint_arm2"/>
  </actuator>
</mujoco>
